<?xml version="1.0" encoding="utf-8"?>
<!-- This URDF was automatically created by SolidWorks to URDF Exporter! Originally created by Stephen Brawner (brawner@gmail.com) 
     Commit Version: 1.4.2-27-gc3b3358  Build Version: 1.4.6891.25992
     For more information, please see http://wiki.ros.org/sw_urdf_exporter -->
<robot
  name="brrobot_support">
  <link name="world"/>
  <joint name="fixed" type="fixed">
    <parent link="world"/>
    <child link="base_link"/>
  </joint>
  <link
    name="base_link">
    <inertial>
      <origin
        xyz="-0.049728 7.1768E-08 0.08267"
        rpy="0 0 0" />
      <mass
        value="20.922" />
      <inertia
        ixx="0.19908"
        ixy="1.9487E-07"
        ixz="0.010228"
        iyy="0.3994"
        iyz="5.5752E-08"
        izz="0.49351" />
    </inertial>
    <visual>
      <origin
        xyz="0 0 0"
        rpy="0 0 0" />
      <geometry>
        <mesh
          filename="package://brrobot_support/meshes/base_link.STL" />
      </geometry>
      <material
        name="">
        <color
          rgba="0.79216 0.81961 0.93333 1" />
      </material>
    </visual>
    <collision>
      <origin
        xyz="0 0 0"
        rpy="0 0 0" />
      <geometry>
        <mesh
          filename="package://brrobot_support/meshes/base_link.STL" />
      </geometry>
    </collision>
  </link>
  <link
    name="link_1">
    <inertial>
      <origin
        xyz="0.058419 0.01861 0.15087"
        rpy="0 0 0" />
      <mass
        value="25.285" />
      <inertia
        ixx="0.32151"
        ixy="-0.047397"
        ixz="-0.10924"
        iyy="0.51929"
        iyz="-0.02335"
        izz="0.48128" />
    </inertial>
    <visual>
      <origin
        xyz="0 0 0"
        rpy="0 0 0" />
      <geometry>
        <mesh
          filename="package://brrobot_support/meshes/link_1.STL" />
      </geometry>
      <material
        name="">
        <color
          rgba="0.79216 0.81961 0.93333 1" />
      </material>
    </visual>
    <collision>
      <origin
        xyz="0 0 0"
        rpy="0 0 0" />
      <geometry>
        <mesh
          filename="package://brrobot_support/meshes/link_1.STL" />
      </geometry>
    </collision>
  </link>
  <joint
    name="joint_1"
    type="revolute">
    <origin
      xyz="0 0 0.177"
      rpy="0 0 0" />
    <parent
      link="base_link" />
    <child
      link="link_1" />
    <axis
      xyz="0 0 1" />
    <limit
      lower="-2.8798"
      upper="2.8798"
      effort="100"
      velocity="3" />
  </joint>
  <link
    name="link_2">
    <inertial>
      <origin
        xyz="0.026787 -0.28219 0.079462"
        rpy="0 0 0" />
      <mass
        value="15.23" />
      <inertia
        ixx="0.85504"
        ixy="0.04009"
        ixz="-0.0042243"
        iyy="0.061785"
        iyz="0.0050321"
        izz="0.8647" />
    </inertial>
    <visual>
      <origin
        xyz="0 0 0"
        rpy="0 0 0" />
      <geometry>
        <mesh
          filename="package://brrobot_support/meshes/link_2.STL" />
      </geometry>
      <material
        name="">
        <color
          rgba="0.79216 0.81961 0.93333 1" />
      </material>
    </visual>
    <collision>
      <origin
        xyz="0 0 0"
        rpy="0 0 0" />
      <geometry>
        <mesh
          filename="package://brrobot_support/meshes/link_2.STL" />
      </geometry>
    </collision>
  </link>
  <joint
    name="joint_2"
    type="revolute">
    <origin
      xyz="0.16933 -0.1025 0.21503"
      rpy="-1.5708 0 3.1416" />
    <parent
      link="link_1" />
    <child
      link="link_2" />
    <axis
      xyz="0 0 1" />
    <limit
      lower="-1.6581"
      upper="1.2217"
      effort="100"
      velocity="3" />
  </joint>
  <link
    name="link_3">
    <inertial>
      <origin
        xyz="0.0059341 -0.071978 0.11985"
        rpy="0 0 0" />
      <mass
        value="10.493" />
      <inertia
        ixx="0.11794"
        ixy="0.0037363"
        ixz="0.00089381"
        iyy="0.074137"
        iyz="-0.010842"
        izz="0.11113" />
    </inertial>
    <visual>
      <origin
        xyz="0 0 0"
        rpy="0 0 0" />
      <geometry>
        <mesh
          filename="package://brrobot_support/meshes/link_3.STL" />
      </geometry>
      <material
        name="">
        <color
          rgba="0.79216 0.81961 0.93333 1" />
      </material>
    </visual>
    <collision>
      <origin
        xyz="0 0 0"
        rpy="0 0 0" />
      <geometry>
        <mesh
          filename="package://brrobot_support/meshes/link_3.STL" />
      </geometry>
    </collision>
  </link>
  <joint
    name="joint_3"
    type="revolute">
    <origin
      xyz="0.02522 -0.64993 0"
      rpy="-3.1416 0 3.1416" />
    <parent
      link="link_2" />
    <child
      link="link_3" />
    <axis
      xyz="0 0 -1" />
    <limit
      lower="-1.4835"
      upper="1.6581"
      effort="100"
      velocity="3" />
  </joint>
  <link
    name="link_4">
    <inertial>
      <origin
        xyz="4.1836E-08 -0.0051512 0.29261"
        rpy="0 0 0" />
      <mass
        value="4.8389" />
      <inertia
        ixx="0.11888"
        ixy="-2.2776E-10"
        ixz="9.5389E-09"
        iyy="0.11202"
        iyz="0.0027621"
        izz="0.014118" />
    </inertial>
    <visual>
      <origin
        xyz="0 0 0"
        rpy="0 0 0" />
      <geometry>
        <mesh
          filename="package://brrobot_support/meshes/link_4.STL" />
      </geometry>
      <material
        name="">
        <color
          rgba="0.79216 0.81961 0.93333 1" />
      </material>
    </visual>
    <collision>
      <origin
        xyz="0 0 0"
        rpy="0 0 0" />
      <geometry>
        <mesh
          filename="package://brrobot_support/meshes/link_4.STL" />
      </geometry>
    </collision>
  </link>
  <joint
    name="joint_4"
    type="revolute">
    <origin
      xyz="0.133 -0.15574 0.1055"
      rpy="-1.5708 0 -1.5708" />
    <parent
      link="link_3" />
    <child
      link="link_4" />
    <axis
      xyz="0 0 1" />
    <limit
      lower="-3.1416"
      upper="3.1416"
      effort="100"
      velocity="3" />
  </joint>
  <link
    name="link_5">
    <inertial>
      <origin
        xyz="-3.1727E-06 0.02581 -2.3376E-11"
        rpy="0 0 0" />
      <mass
        value="1.1224" />
      <inertia
        ixx="0.002587"
        ixy="2.464E-07"
        ixz="5.046E-10"
        iyy="0.0014218"
        iyz="1.6148E-12"
        izz="0.0028805" />
    </inertial>
    <visual>
      <origin
        xyz="0 0 0"
        rpy="0 0 0" />
      <geometry>
        <mesh
          filename="package://brrobot_support/meshes/link_5.STL" />
      </geometry>
      <material
        name="">
        <color
          rgba="0.79216 0.81961 0.93333 1" />
      </material>
    </visual>
    <collision>
      <origin
        xyz="0 0 0"
        rpy="0 0 0" />
      <geometry>
        <mesh
          filename="package://brrobot_support/meshes/link_5.STL" />
      </geometry>
    </collision>
  </link>
  <joint
    name="joint_5"
    type="revolute">
    <origin
      xyz="0 0 0.474"
      rpy="1.5708 0 0" />
    <parent
      link="link_4" />
    <child
      link="link_5" />
    <axis
      xyz="0 0 -1" />
    <limit
      lower="-2.0071"
      upper="2.0071"
      effort="100"
      velocity="3" />
  </joint>
  <link
    name="link_6">
    <inertial>
      <origin
        xyz="-1.6833E-05 5.3776E-16 0.022885"
        rpy="0 0 0" />
      <mass
        value="0.32394" />
      <inertia
        ixx="0.00023753"
        ixy="-6.2478E-08"
        ixz="-6.6739E-08"
        iyy="0.0002374"
        iyz="-1.2756E-17"
        izz="0.00034886" />
    </inertial>
    <visual>
      <origin
        xyz="0 0 0"
        rpy="0 0 0" />
      <geometry>
        <mesh
          filename="package://brrobot_support/meshes/link_6.STL" />
      </geometry>
      <material
        name="">
        <color
          rgba="0.79216 0.81961 0.93333 1" />
      </material>
    </visual>
    <collision>
      <origin
        xyz="0 0 0"
        rpy="0 0 0" />
      <geometry>
        <mesh
          filename="package://brrobot_support/meshes/link_6.STL" />
      </geometry>
    </collision>
  </link>
  <joint
    name="joint_6"
    type="revolute">
    <origin
      xyz="0 0.102 0"
      rpy="-1.5708 0 0" />
    <parent
      link="link_5" />
    <child
      link="link_6" />
    <axis
      xyz="0 0 1" />
    <limit
      lower="-6.2832"
      upper="6.2832"
      effort="100"
      velocity="3" />
  </joint>
  <link
    name="last_link">
    <inertial>
      <origin
        xyz="-0.00094656 -0.023469 0.025359"
        rpy="0 0 0" />
      <mass
        value="0.12941" />
      <inertia
        ixx="0.00018203"
        ixy="-1.3413E-06"
        ixz="2.1618E-06"
        iyy="0.00015413"
        iyz="5.3131E-05"
        izz="0.00016514" />
    </inertial>
    <visual>
      <origin
        xyz="0 0 0"
        rpy="0 0 0" />
      <geometry>
        <mesh
          filename="package://brrobot_support/meshes/last_link.STL" />
      </geometry>
      <material
        name="">
        <color
          rgba="0.75294 0.75294 0.75294 1" />
      </material>
    </visual>
    <collision>
      <origin
        xyz="0 0 0"
        rpy="0 0 0" />
      <geometry>
        <mesh
          filename="package://brrobot_support/meshes/last_link.STL" />
      </geometry>
    </collision>
  </link>
  <joint
    name="last_joint"
    type="fixed">
    <origin
      xyz="0 0 0.052"
      rpy="0 0 0" />
    <parent
      link="link_6" />
    <child
      link="last_link" />
    <axis
      xyz="0 0 0" />
    <limit
      lower="0"
      upper="0"
      effort="0"
      velocity="0" />
  </joint>
</robot>
