<?xml version="1.0" encoding="utf-8"?>
<!-- This URDF was automatically created by SolidWorks to URDF Exporter! Originally created by Stephen Brawner (brawner@gmail.com) 
     Commit Version: 1.4.2-27-gc3b3358  Build Version: 1.4.6891.25992
     For more information, please see http://wiki.ros.org/sw_urdf_exporter -->
<robot
  name="brrobot_support">
  <link name="world"/>
  <joint name="fixed" type="fixed">
    <parent link="world"/>
    <child link="base_link"/>
  </joint>
  <link
    name="base_link">
    <inertial>
      <origin
        xyz="-0.049728 7.1768E-08 0.08267"
        rpy="0 0 0" />
      <mass
        value="0.00001" />
      <inertia
        ixx="10"
        ixy="0"
        ixz="0"
        iyy="10"
        iyz="0"
        izz="10" />
    </inertial>
    <visual>
      <origin
        xyz="0 0 0"
        rpy="0 0 0" />
      <geometry>
        <mesh
          filename="package://brrobot_support/meshes/base_link.STL" />
      </geometry>
      <material
        name="">
        <color
          rgba="0.79216 0.81961 0.93333 1" />
      </material>
    </visual>
    <collision>
      <origin
        xyz="0 0 0"
        rpy="0 0 0" />
      <geometry>
        <mesh
          filename="package://brrobot_support/meshes/base_link.STL" />
      </geometry>
    </collision>
  </link>
  <link
    name="link_1">
    <inertial>
      <origin
        xyz="0.058419 0.01861 0.15087"
        rpy="0 0 0" />
      <mass
        value="0.00001" />
      <inertia
        ixx="10"
        ixy="0"
        ixz="0"
        iyy="10"
        iyz="0"
        izz="10" />
    </inertial>
    <visual>
      <origin
        xyz="0 0 0"
        rpy="0 0 0" />
      <geometry>
        <mesh
          filename="package://brrobot_support/meshes/link_1.STL" />
      </geometry>
      <material
        name="">
        <color
          rgba="0.79216 0.81961 0.93333 1" />
      </material>
    </visual>
    <collision>
      <origin
        xyz="0 0 0"
        rpy="0 0 0" />
      <geometry>
        <mesh
          filename="package://brrobot_support/meshes/link_1.STL" />
      </geometry>
    </collision>
  </link>
  <joint
    name="joint_1"
    type="revolute">
    <origin
      xyz="0 0 0.177"
      rpy="0 0 0" />
    <parent
      link="base_link" />
    <child
      link="link_1" />
    <axis
      xyz="0 0 1" />
    <limit
      lower="-2.8798"
      upper="2.8798"
      effort="100"
      velocity="3" />
  </joint>
  <link
    name="link_2">
    <inertial>
      <origin
        xyz="0.026787 -0.28219 0.079462"
        rpy="0 0 0" />
      <mass
        value="0.00001" />
      <inertia
        ixx="10"
        ixy="0"
        ixz="0"
        iyy="10"
        iyz="0"
        izz="10" />
    </inertial>
    <visual>
      <origin
        xyz="0 0 0"
        rpy="0 0 0" />
      <geometry>
        <mesh
          filename="package://brrobot_support/meshes/link_2.STL" />
      </geometry>
      <material
        name="">
        <color
          rgba="0.79216 0.81961 0.93333 1" />
      </material>
    </visual>
    <collision>
      <origin
        xyz="0 0 0"
        rpy="0 0 0" />
      <geometry>
        <mesh
          filename="package://brrobot_support/meshes/link_2.STL" />
      </geometry>
    </collision>
  </link>
  <joint
    name="joint_2"
    type="revolute">
    <origin
      xyz="0.16933 -0.1025 0.21503"
      rpy="-1.5708 0 3.1416" />
    <parent
      link="link_1" />
    <child
      link="link_2" />
    <axis
      xyz="0 0 -1" />
    <limit
      lower="-1.6581"
      upper="1.2217"
      effort="100"
      velocity="3" />
  </joint>
  <link
    name="link_3">
    <inertial>
      <origin
        xyz="0.0059341 -0.071978 0.11985"
        rpy="0 0 0" />
      <mass
        value="0.00001" />
      <inertia
        ixx="10"
        ixy="0"
        ixz="0"
        iyy="10"
        iyz="0"
        izz="10" />
    </inertial>
    <visual>
      <origin
        xyz="0 0 0"
        rpy="0 0 0" />
      <geometry>
        <mesh
          filename="package://brrobot_support/meshes/link_3.STL" />
      </geometry>
      <material
        name="">
        <color
          rgba="0.79216 0.81961 0.93333 1" />
      </material>
    </visual>
    <collision>
      <origin
        xyz="0 0 0"
        rpy="0 0 0" />
      <geometry>
        <mesh
          filename="package://brrobot_support/meshes/link_3.STL" />
      </geometry>
    </collision>
  </link>
  <joint
    name="joint_3"
    type="revolute">
    <origin
      xyz="0.02522 -0.64993 0"
      rpy="-3.1416 0 3.1416" />
    <parent
      link="link_2" />
    <child
      link="link_3" />
    <axis
      xyz="0 0 1" />
    <limit
      lower="-1.4835"
      upper="1.6581"
      effort="100"
      velocity="3" />
  </joint>
  <link
    name="link_4">
    <inertial>
      <origin
        xyz="4.1836E-08 -0.0051512 0.29261"
        rpy="0 0 0" />
      <mass
        value="0.00001" />
      <inertia
        ixx="10"
        ixy="0"
        ixz="0"
        iyy="10"
        iyz="0"
        izz="10" />
    </inertial>
    </inertial>
    <visual>
      <origin
        xyz="0 0 0"
        rpy="0 0 0" />
      <geometry>
        <mesh
          filename="package://brrobot_support/meshes/link_4.STL" />
      </geometry>
      <material
        name="">
        <color
          rgba="0.79216 0.81961 0.93333 1" />
      </material>
    </visual>
    <collision>
      <origin
        xyz="0 0 0"
        rpy="0 0 0" />
      <geometry>
        <mesh
          filename="package://brrobot_support/meshes/link_4.STL" />
      </geometry>
    </collision>
  </link>
  <joint
    name="joint_4"
    type="revolute">
    <origin
      xyz="0.133 -0.15574 0.1055"
      rpy="-1.5708 0 -1.5708" />
    <parent
      link="link_3" />
    <child
      link="link_4" />
    <axis
      xyz="0 0 1" />
    <limit
      lower="-3.1416"
      upper="3.1416"
      effort="100"
      velocity="3" />
  </joint>
  <link
    name="link_5">
    <inertial>
      <origin
        xyz="-3.1727E-06 0.02581 -2.3376E-11"
        rpy="0 0 0" />
      <mass
        value="0.00001" />
      <inertia
        ixx="10"
        ixy="0"
        ixz="0"
        iyy="10"
        iyz="0"
        izz="10" />
    </inertial>
    <visual>
      <origin
        xyz="0 0 0"
        rpy="0 0 0" />
      <geometry>
        <mesh
          filename="package://brrobot_support/meshes/link_5.STL" />
      </geometry>
      <material
        name="">
        <color
          rgba="0.79216 0.81961 0.93333 1" />
      </material>
    </visual>
    <collision>
      <origin
        xyz="0 0 0"
        rpy="0 0 0" />
      <geometry>
        <mesh
          filename="package://brrobot_support/meshes/link_5.STL" />
      </geometry>
    </collision>
  </link>
  <joint
    name="joint_5"
    type="revolute">
    <origin
      xyz="0 0 0.474"
      rpy="1.5708 0 0" />
    <parent
      link="link_4" />
    <child
      link="link_5" />
    <axis
      xyz="0 0 1" />
    <limit
      lower="-2.0071"
      upper="2.0071"
      effort="100"
      velocity="3" />
  </joint>
  <link
    name="link_6">
    <inertial>
      <origin
        xyz="-1.6833E-05 5.3776E-16 0.022885"
        rpy="0 0 0" />
      <mass
        value="0.00001" />
      <inertia
        ixx="10"
        ixy="0"
        ixz="0"
        iyy="10"
        iyz="0"
        izz="10" />
    </inertial>
    <visual>
      <origin
        xyz="0 0 0"
        rpy="0 0 0" />
      <geometry>
        <mesh
          filename="package://brrobot_support/meshes/link_6.STL" />
      </geometry>
      <material
        name="">
        <color
          rgba="0.79216 0.81961 0.93333 1" />
      </material>
    </visual>
    <collision>
      <origin
        xyz="0 0 0"
        rpy="0 0 0" />
      <geometry>
        <mesh
          filename="package://brrobot_support/meshes/link_6.STL" />
      </geometry>
    </collision>
  </link>
  <joint
    name="joint_6"
    type="revolute">
    <origin
      xyz="0 0.102 0"
      rpy="-1.5708 0 0" />
    <parent
      link="link_5" />
    <child
      link="link_6" />
    <axis
      xyz="0 0 -1" />
    <limit
      lower="-6.2832"
      upper="6.2832"
      effort="100"
      velocity="3" />
  </joint>
  <link
    name="last_link">
    <inertial>
      <origin
        xyz="-0.00094656 -0.023469 0.025359"
        rpy="0 0 0" />
      <mass
        value="0.00001" />
      <inertia
        ixx="10"
        ixy="0"
        ixz="0"
        iyy="10"
        iyz="0"
        izz="10" />
    </inertial>
    <visual>
      <origin
        xyz="0 0 0"
        rpy="0 0 0" />
      <geometry>
        <mesh
          filename="package://brrobot_support/meshes/last_link.STL" />
      </geometry>
      <material
        name="">
        <color
          rgba="0.75294 0.75294 0.75294 1" />
      </material>
    </visual>
    <collision>
      <origin
        xyz="0 0 0"
        rpy="0 0 0" />
      <geometry>
        <mesh
          filename="package://brrobot_support/meshes/last_link.STL" />
      </geometry>
    </collision>
  </link>
  <joint
    name="last_joint"
    type="fixed">
    <origin
      xyz="0 0 0.052"
      rpy="0 0 0" />
    <parent
      link="link_6" />
    <child
      link="last_link" />
    <axis
      xyz="0 0 0" />
    <limit
      lower="0"
      upper="0"
      effort="0"
      velocity="0" />
  </joint>
</robot>
